Workbook

Sheet events-入力用
A1: country_iso3 | B1: country_name | C1: country_name_ja | D1: title | E1: summary | F1: detail | G1: 関係国１ | H1: 関係国２ | I1: 関係国３ | J1: related_country_1 | K1: related_country_2 | L1: related_country_3 | M1: related_countries | N1: impact_summary | O1: category | P1: event_date | Q1: source_name | R1: source_url | S1: importance
A2: =IF(C2="","",VLOOKUP(C2,[1]ISO辞書!A:C,2,FALSE)) -> UKR | B2: =IF(C2="","",VLOOKUP(C2,[1]ISO辞書!A:C,3,FALSE)) -> Ukraine | C2: ウクライナ | D2: ウクライナとトルコの首脳会談 | E2: 両国の安全保障協力の強化やエネルギー調達分野での連携を確認。 | F2: 国際関係 | G2: トルコ | J2: =IF(G2="","",VLOOKUP(G2,[1]ISO辞書!A:B,2,FALSE)) -> TUR | K2: =IF(H2="","",VLOOKUP(H2,[1]ISO辞書!A:B,2,FALSE)) | L2: =IF(I2="","",VLOOKUP(I2,[1]ISO辞書!A:B,2,FALSE)) | M2: =_xlfn.TEXTJOIN(";",TRUE,J2:L2) -> TUR | N2: 外交関係が改善 | O2: 安全保障 | P2: 46116 | Q2: Reuters | R2: https://www.reuters.com/business/aerospace-defense/zelenskiy-arrives-istanbul-talks-with-erdogan-2026-04-04/ | S2: 4
A3: =IF(C3="","",VLOOKUP(C3,[1]ISO辞書!A:C,2,FALSE)) -> ITA | B3: =IF(C3="","",VLOOKUP(C3,[1]ISO辞書!A:C,3,FALSE)) -> Italy | C3: イタリア | D3: 伊メローニ首相の中東訪問 | E3: 湾岸諸国訪問にてエネルギー供給確保と安全支援の強化を協議 | G3: サウジアラビア | H3: カタール | I3: UAE | J3: =IF(G3="","",VLOOKUP(G3,[1]ISO辞書!A:B,2,FALSE)) -> SAU | K3: =IF(H3="","",VLOOKUP(H3,[1]ISO辞書!A:B,2,FALSE)) -> QAT | L3: =IF(I3="","",VLOOKUP(I3,[1]ISO辞書!A:B,2,FALSE)) -> ARE | M3: =_xlfn.TEXTJOIN(";",TRUE,J3:L3) -> SAU;QAT;ARE | N3: 外交関係が改善 | O3: 外交 | P3: 46115 | Q3: Reuters | R3: https://www.reuters.com/world/europe/italys-meloni-flies-gulf-region-energy-security-push-2026-04-03/ | S3: 3
A4: =IF(C4="","",VLOOKUP(C4,[1]ISO辞書!A:C,2,FALSE)) -> KOR | B4: =IF(C4="","",VLOOKUP(C4,[1]ISO辞書!A:C,3,FALSE)) -> Korea | C4: 韓国 | D4: 韓国とフランスの首脳会談 | E4: 防衛協力と経済エネルギー連携を確認 | F4: 国際関係 | G4: フランス | J4: =IF(G4="","",VLOOKUP(G4,[1]ISO辞書!A:B,2,FALSE)) -> FRA | K4: =IF(H4="","",VLOOKUP(H4,[1]ISO辞書!A:B,2,FALSE)) | L4: =IF(I4="","",VLOOKUP(I4,[1]ISO辞書!A:B,2,FALSE)) | M4: =_xlfn.TEXTJOIN(";",TRUE,J4:L4) -> FRA | N4: 外交関係が改善 | O4: 外交 | P4: 46115 | Q4: Reuters | R4: https://www.reuters.com/world/asia-pacific/south-korea-france-upgrade-ties-strategic-partnership-blue-house-says-2026-04-03/ | S4: 3
A5: =IF(C5="","",VLOOKUP(C5,[1]ISO辞書!A:C,2,FALSE)) -> RUS | B5: =IF(C5="","",VLOOKUP(C5,[1]ISO辞書!A:C,3,FALSE)) -> Russian Federation | C5: ロシア | D5: ロ軍がハリコフへドローン攻撃を継続 | F5: 紛争 | G5: ウクライナ | J5: =IF(G5="","",VLOOKUP(G5,[1]ISO辞書!A:B,2,FALSE)) -> UKR | K5: =IF(H5="","",VLOOKUP(H5,[1]ISO辞書!A:B,2,FALSE)) | L5: =IF(I5="","",VLOOKUP(I5,[1]ISO辞書!A:B,2,FALSE)) | M5: =_xlfn.TEXTJOIN(";",TRUE,J5:L5) -> UKR | N5: 軍事的緊張が高まる | O5: 紛争 | P5: 46114 | Q5: Reuters | R5: https://www.reuters.com/world/russian-forces-maintain-day-long-drone-barrage-ukraines-kharkiv-2026-04-02/ | S5: 4
A6: =IF(C6="","",VLOOKUP(C6,[1]ISO辞書!A:C,2,FALSE)) -> GBR | B6: =IF(C6="","",VLOOKUP(C6,[1]ISO辞書!A:C,3,FALSE)) -> Britain | C6: イギリス | D6: ホルムズ海峡封鎖問題に40カ国が協議 | E6: 40カ国がイランによるホルムズ海峡封鎖問題について連合を結成し協議 | F6: 国際関係 | G6: ドイツ | H6: フランス | I6: UAE | J6: =IF(G6="","",VLOOKUP(G6,[1]ISO辞書!A:B,2,FALSE)) -> DEU | K6: =IF(H6="","",VLOOKUP(H6,[1]ISO辞書!A:B,2,FALSE)) -> FRA | L6: =IF(I6="","",VLOOKUP(I6,[1]ISO辞書!A:B,2,FALSE)) -> ARE | M6: =_xlfn.TEXTJOIN(";",TRUE,J6:L6) -> DEU;FRA;ARE | N6: エネルギー市場に影響 | O6: エネルギー | P6: 46114 | Q6: Reuters | R6: https://www.reuters.com/business/energy/dozens-countries-discuss-coalition-secure-passage-through-strait-hormuz-2026-04-02/ | S6: 5
A7: =IF(C7="","",VLOOKUP(C7,[1]ISO辞書!A:C,2,FALSE)) -> USA | B7: =IF(C7="","",VLOOKUP(C7,[1]ISO辞書!A:C,3,FALSE)) -> America | C7: アメリカ | D7: 米トランプ大統領がNATO脱退を仄めかす | E7: 欧州の支援拒否を理由にNATO離脱を示唆、各国が強く反発 | F7: 国際関係 | J7: =IF(G7="","",VLOOKUP(G7,[1]ISO辞書!A:B,2,FALSE)) | K7: =IF(H7="","",VLOOKUP(H7,[1]ISO辞書!A:B,2,FALSE)) | L7: =IF(I7="","",VLOOKUP(I7,[1]ISO辞書!A:B,2,FALSE)) | M7: =_xlfn.TEXTJOIN(";",TRUE,J7:L7) | N7: 外交関係が悪化 | P7: 46113 | Q7: Reuters | R7: https://www.reuters.com/business/aerospace-defense/trump-threatens-nato-exit-scaling-up-tensions-with-allies-2026-04-01/ | S7: 4
A8: =IF(C8="","",VLOOKUP(C8,[1]ISO辞書!A:C,2,FALSE)) -> SRB | B8: =IF(C8="","",VLOOKUP(C8,[1]ISO辞書!A:C,3,FALSE)) -> Serbia | C8: セルビア | D8: セルビア首都での大規模抗議活動 | E8: 市内で学生らがデモ中に衝突、複数負傷・数人逮捕と報告。 | F8: 国内政治 | J8: =IF(G8="","",VLOOKUP(G8,[1]ISO辞書!A:B,2,FALSE)) | K8: =IF(H8="","",VLOOKUP(H8,[1]ISO辞書!A:B,2,FALSE)) | L8: =IF(I8="","",VLOOKUP(I8,[1]ISO辞書!A:B,2,FALSE)) | M8: =_xlfn.TEXTJOIN(";",TRUE,J8:L8) | N8: 国内政治に影響 | O8: 国内政治 | P8: 46112 | Q8: Reuters | R8: https://www.reuters.com/world/serbian-students-protesters-clash-with-police-belgrade-2026-03-31/ | S8: 3
A9: =IF(C9="","",VLOOKUP(C9,[1]ISO辞書!A:C,2,FALSE)) -> IRN | B9: =IF(C9="","",VLOOKUP(C9,[1]ISO辞書!A:C,3,FALSE)) -> Iran | C9: イラン | D9: イラン政府が反体制派関係者2名を処刑と発表 | F9: 国内政治 | J9: =IF(G9="","",VLOOKUP(G9,[1]ISO辞書!A:B,2,FALSE)) | K9: =IF(H9="","",VLOOKUP(H9,[1]ISO辞書!A:B,2,FALSE)) | L9: =IF(I9="","",VLOOKUP(I9,[1]ISO辞書!A:B,2,FALSE)) | M9: =_xlfn.TEXTJOIN(";",TRUE,J9:L9) | N9: 国内政治に影響 | O9: 国内政治 | P9: 46116 | Q9: Reuters | R9: https://www.reuters.com/world/middle-east/iran-executes-two-linked-opposition-group-media-say-2026-04-04/ | S9: 3
A10: =IF(C10="","",VLOOKUP(C10,[1]ISO辞書!A:C,2,FALSE)) -> IND | B10: =IF(C10="","",VLOOKUP(C10,[1]ISO辞書!A:C,3,FALSE)) -> India | C10: インド | D10: インドが約7年ぶりにイラン産原油を調達 | F10: 国際関係 | G10: イラン | J10: =IF(G10="","",VLOOKUP(G10,[1]ISO辞書!A:B,2,FALSE)) -> IRN | K10: =IF(H10="","",VLOOKUP(H10,[1]ISO辞書!A:B,2,FALSE)) | L10: =IF(I10="","",VLOOKUP(I10,[1]ISO辞書!A:B,2,FALSE)) | M10: =_xlfn.TEXTJOIN(";",TRUE,J10:L10) -> IRN | N10: エネルギー市場に影響 | O10: エネルギー | P10: 46116 | Q10: Reuters | R10: https://www.reuters.com/business/energy/india-says-crude-oil-supplies-secured-no-payment-issues-iran-imports-2026-04-04/ | S10: 4
A11: =IF(C11="","",VLOOKUP(C11,[1]ISO辞書!A:C,2,FALSE)) -> RUS | B11: =IF(C11="","",VLOOKUP(C11,[1]ISO辞書!A:C,3,FALSE)) -> Russian Federation | C11: ロシア | D11: ロシアとトルコ首脳の電話会談 | E11: 両首脳が中東情勢を協議、地域安定へ情報共有と調整で一致を確認 | F11: 国際関係 | G11: トルコ | J11: =IF(G11="","",VLOOKUP(G11,[1]ISO辞書!A:B,2,FALSE)) -> TUR | K11: =IF(H11="","",VLOOKUP(H11,[1]ISO辞書!A:B,2,FALSE)) | L11: =IF(I11="","",VLOOKUP(I11,[1]ISO辞書!A:B,2,FALSE)) | M11: =_xlfn.TEXTJOIN(";",TRUE,J11:L11) -> TUR | N11: 国際関係に影響 | O11: 外交 | P11: 46115 | Q11: Reuters | R11: https://www.reuters.com/world/middle-east/putin-holds-call-with-turkeys-erdogan-discuss-middle-east-2026-04-03/ | S11: 4
A12: =IF(C12="","",VLOOKUP(C12,[1]ISO辞書!A:C,2,FALSE)) -> JPN | B12: =IF(C12="","",VLOOKUP(C12,[1]ISO辞書!A:C,3,FALSE)) -> Japan | C12: 日本 | D12: 日本等カ国の船舶がホルムズ海峡を通過 | F12: 国際関係 | G12: フランス | H12: オマーン | I12: イラン | J12: =IF(G12="","",VLOOKUP(G12,[1]ISO辞書!A:B,2,FALSE)) -> FRA | K12: =IF(H12="","",VLOOKUP(H12,[1]ISO辞書!A:B,2,FALSE)) -> OMN | L12: =IF(I12="","",VLOOKUP(I12,[1]ISO辞書!A:B,2,FALSE)) -> IRN | M12: =_xlfn.TEXTJOIN(";",TRUE,J12:L12) -> FRA;OMN;IRN | N12: エネルギー市場に影響 | O12: エネルギー | P12: 46115 | Q12: Reuters | R12: https://www.reuters.com/business/energy/japanese-owned-lng-tanker-crosses-strait-hormuz-2026-04-03/ | S12: 4
A13: =IF(C13="","",VLOOKUP(C13,[1]ISO辞書!A:C,2,FALSE)) -> LBN | B13: =IF(C13="","",VLOOKUP(C13,[1]ISO辞書!A:C,3,FALSE)) -> Lebanon | C13: レバノン | D13: イスラエル空爆でヒズボラ最高司令官が死亡 | F13: 紛争 | G13: イスラエル | J13: =IF(G13="","",VLOOKUP(G13,[1]ISO辞書!A:B,2,FALSE)) -> ISR | K13: =IF(H13="","",VLOOKUP(H13,[1]ISO辞書!A:B,2,FALSE)) | L13: =IF(I13="","",VLOOKUP(I13,[1]ISO辞書!A:B,2,FALSE)) | M13: =_xlfn.TEXTJOIN(";",TRUE,J13:L13) -> ISR | N13: 軍事的緊張が高まる | O13: 紛争 | P13: 46113 | Q13: Reuters | R13: https://www.reuters.com/world/middle-east/israeli-military-says-strike-beirut-killed-hezbollah-southern-front-commander-2026-04-01/ | S13: 4
A14: =IF(C14="","",VLOOKUP(C14,[1]ISO辞書!A:C,2,FALSE)) -> SYR | B14: =IF(C14="","",VLOOKUP(C14,[1]ISO辞書!A:C,3,FALSE)) -> Syrian Arab Republic | C14: シリア | D14: シリア暫定大統領がイラン紛争不干渉を表明 | E14: 「攻撃されない限り参戦せず」と表明、国境強化と外交重視を強調 | F14: 国際関係 | G14: イラン | H14: アメリカ | I14: イスラエル | J14: =IF(G14="","",VLOOKUP(G14,[1]ISO辞書!A:B,2,FALSE)) -> IRN | K14: =IF(H14="","",VLOOKUP(H14,[1]ISO辞書!A:B,2,FALSE)) -> USA | L14: =IF(I14="","",VLOOKUP(I14,[1]ISO辞書!A:B,2,FALSE)) -> ISR | M14: =_xlfn.TEXTJOIN(";",TRUE,J14:L14) -> IRN;USA;ISR | N14: 国際関係に影響 | O14: 外交 | P14: 46112 | Q14: Reuters | R14: https://www.reuters.com/world/europe/syria-will-stay-out-iran-conflict-unless-it-faces-aggression-president-says-2026-03-31/ | S14: 3
A15: =IF(C15="","",VLOOKUP(C15,[1]ISO辞書!A:C,2,FALSE)) -> ARG | B15: =IF(C15="","",VLOOKUP(C15,[1]ISO辞書!A:C,3,FALSE)) -> Argentina | C15: アルゼンチン | D15: アルゼンチンがイラン革命防衛隊をテロ組織に指定 | E15: アメリカと歩調を合わせ、金融制裁適用が可能に | F15: 国際関係 | G15: イラン | J15: =IF(G15="","",VLOOKUP(G15,[1]ISO辞書!A:B,2,FALSE)) -> IRN | K15: =IF(H15="","",VLOOKUP(H15,[1]ISO辞書!A:B,2,FALSE)) | L15: =IF(I15="","",VLOOKUP(I15,[1]ISO辞書!A:B,2,FALSE)) | M15: =_xlfn.TEXTJOIN(";",TRUE,J15:L15) -> IRN | N15: 国際関係に影響 | O15: 外交 | P15: 46113 | Q15: Reuters | R15: https://www.reuters.com/world/middle-east/argentina-designates-irans-irgc-terrorist-organization-aligning-with-us-2026-04-01/ | S15: 4
A16: =IF(C16="","",VLOOKUP(C16,[1]ISO辞書!A:C,2,FALSE)) -> BFA | B16: =IF(C16="","",VLOOKUP(C16,[1]ISO辞書!A:C,3,FALSE)) -> Burkina Faso | C16: ブルキナファソ | D16: ブルキナファソ軍による民間人犠牲増報告 | E16: 同国とマリにて軍事政権が民間人を多数殺害と人権団体が発表 | F16: 国際関係 | G16: マリ | J16: =IF(G16="","",VLOOKUP(G16,[1]ISO辞書!A:B,2,FALSE)) -> MLI | K16: =IF(H16="","",VLOOKUP(H16,[1]ISO辞書!A:B,2,FALSE)) | L16: =IF(I16="","",VLOOKUP(I16,[1]ISO辞書!A:B,2,FALSE)) | M16: =_xlfn.TEXTJOIN(";",TRUE,J16:L16) -> MLI | N16: 軍事的緊張が高まる | O16: 紛争 | P16: 46114 | Q16: Reuters | R16: https://www.reuters.com/world/africa/burkina-mali-troops-kill-more-civilians-than-jihadists-do-data-shows-2026-04-02/ | S16: 3
A17: =IF(C17="","",VLOOKUP(C17,[1]ISO辞書!A:C,2,FALSE)) -> ETH | B17: =IF(C17="","",VLOOKUP(C17,[1]ISO辞書!A:C,3,FALSE)) -> Ethiopia | C17: エチオピア | D17: エチオピアと中国が債務問題で合意 | E17: G20の共通枠組みで債務処理に両国が合意、再編と新融資も協議。 | F17: 国際関係 | G17: 中国 | J17: =IF(G17="","",VLOOKUP(G17,[1]ISO辞書!A:B,2,FALSE)) -> CHN | K17: =IF(H17="","",VLOOKUP(H17,[1]ISO辞書!A:B,2,FALSE)) | L17: =IF(I17="","",VLOOKUP(I17,[1]ISO辞書!A:B,2,FALSE)) | M17: =_xlfn.TEXTJOIN(";",TRUE,J17:L17) -> CHN | N17: 経済に影響 | O17: 経済 | P17: 46115 | Q17: Reuters | R17: https://www.reuters.com/world/africa/ethiopia-says-reaches-resolution-with-china-debt-treatment-2026-04-03/ | S17: 3
A18: =IF(C18="","",VLOOKUP(C18,[1]ISO辞書!A:C,2,FALSE)) -> COD | B18: =IF(C18="","",VLOOKUP(C18,[1]ISO辞書!A:C,3,FALSE)) -> Democratic Republic of the Congo | C18: コンゴ民主共和国 | D18: DRコンゴ東部でIS系反乱が15人殺害 | F18: 紛争 | J18: =IF(G18="","",VLOOKUP(G18,[1]ISO辞書!A:B,2,FALSE)) | K18: =IF(H18="","",VLOOKUP(H18,[1]ISO辞書!A:B,2,FALSE)) | L18: =IF(I18="","",VLOOKUP(I18,[1]ISO辞書!A:B,2,FALSE)) | M18: =_xlfn.TEXTJOIN(";",TRUE,J18:L18) | N18: 地域情勢が不安定化 | O18: 紛争 | P18: 46114 | Q18: Reuters | R18: https://www.reuters.com/world/africa/islamic-state-linked-rebels-kill-15-eastern-congo-officials-say-2026-04-02/ | S18: 2
A19: =IF(C19="","",VLOOKUP(C19,[1]ISO辞書!A:C,2,FALSE)) -> USA | B19: =IF(C19="","",VLOOKUP(C19,[1]ISO辞書!A:C,3,FALSE)) -> America | C19: アメリカ | D19: アメリカがベネズエラ暫定大統領への制裁を解除 | E19: 制裁解除で資産管理や大使館再開の道が開き、国際取引再開に弾み。 | F19: 国際関係 | G19: ベネズエラ | J19: =IF(G19="","",VLOOKUP(G19,[1]ISO辞書!A:B,2,FALSE)) -> VEN | K19: =IF(H19="","",VLOOKUP(H19,[1]ISO辞書!A:B,2,FALSE)) | L19: =IF(I19="","",VLOOKUP(I19,[1]ISO辞書!A:B,2,FALSE)) | M19: =_xlfn.TEXTJOIN(";",TRUE,J19:L19) -> VEN | N19: 外交関係が改善 | O19: 外交 | P19: 46114 | Q19: Reuters | R19: https://www.reuters.com/world/americas/us-lifts-sanctions-venezuelas-interim-president-2026-04-01/ | S19: 4
A20: =IF(C20="","",VLOOKUP(C20,[1]ISO辞書!A:C,2,FALSE)) -> EU | B20: =IF(C20="","",VLOOKUP(C20,[1]ISO辞書!A:C,3,FALSE)) -> EU | C20: 欧州連合 | D20: EUがキューバへ230万ドルを人道支援として拠出 | E20: 電力危機と物資不足を受け、食料と飲料水で最大200万人支援を実施へ。 | F20: 国際関係 | G20: キューバ | J20: =IF(G20="","",VLOOKUP(G20,[1]ISO辞書!A:B,2,FALSE)) -> CUB | K20: =IF(H20="","",VLOOKUP(H20,[1]ISO辞書!A:B,2,FALSE)) | L20: =IF(I20="","",VLOOKUP(I20,[1]ISO辞書!A:B,2,FALSE)) | M20: =_xlfn.TEXTJOIN(";",TRUE,J20:L20) -> CUB | N20: 国際関係に影響 | O20: 外交 | P20: 46113 | Q20: Reuters | R20: https://www.reuters.com/world/americas/eu-announces-further-23-million-humanitarian-aid-cuba-2026-04-01/ | S20: 3
A21: =IF(C21="","",VLOOKUP(C21,[1]ISO辞書!A:C,2,FALSE)) -> CHN | B21: =IF(C21="","",VLOOKUP(C21,[1]ISO辞書!A:C,3,FALSE)) -> China | C21: 中国 | D21: 中国がデジタルヒューマンへの規制を強化 | E21: デジタルヒューマンへの明示表示を義務化、未成年への中毒性のあるサービス提供を禁止 | F21: 国内政治 | J21: =IF(G21="","",VLOOKUP(G21,[1]ISO辞書!A:B,2,FALSE)) | K21: =IF(H21="","",VLOOKUP(H21,[1]ISO辞書!A:B,2,FALSE)) | L21: =IF(I21="","",VLOOKUP(I21,[1]ISO辞書!A:B,2,FALSE)) | M21: =_xlfn.TEXTJOIN(";",TRUE,J21:L21) | N21: 国内政治に影響 | O21: 国内政治 | P21: 46115 | Q21: Reuters | R21: https://www.reuters.com/world/china/china-moves-regulate-digital-humans-bans-addictive-services-children-2026-04-03/ | S21: 3
A22: =IF(C22="","",VLOOKUP(C22,[1]ISO辞書!A:C,2,FALSE)) -> NZL | B22: =IF(C22="","",VLOOKUP(C22,[1]ISO辞書!A:C,3,FALSE)) -> New Zealand | C22: ニュージーランド | D22: ニュージーランドとクック諸島が安全保障宣言に署名 | E22: 安全保障協力を深化させ、領域防衛・海上監視・災害支援で連携強化、制度的枠組みも構築へ | F22: 国際関係 | G22: クック諸島 | J22: =IF(G22="","",VLOOKUP(G22,[1]ISO辞書!A:B,2,FALSE)) -> COK | K22: =IF(H22="","",VLOOKUP(H22,[1]ISO辞書!A:B,2,FALSE)) | L22: =IF(I22="","",VLOOKUP(I22,[1]ISO辞書!A:B,2,FALSE)) | M22: =_xlfn.TEXTJOIN(";",TRUE,J22:L22) -> COK | N22: 外交関係が改善 | O22: 外交 | P22: 46114 | Q22: Reuters | R22: https://www.reuters.com/world/asia-pacific/new-zealand-cook-islands-sign-defence-security-declaration-2026-04-01/ | S22: 4
A23: =IF(C23="","",VLOOKUP(C23,[1]ISO辞書!A:C,2,FALSE)) | B23: =IF(C23="","",VLOOKUP(C23,[1]ISO辞書!A:C,3,FALSE)) | J23: =IF(G23="","",VLOOKUP(G23,[1]ISO辞書!A:B,2,FALSE)) | K23: =IF(H23="","",VLOOKUP(H23,[1]ISO辞書!A:B,2,FALSE)) | L23: =IF(I23="","",VLOOKUP(I23,[1]ISO辞書!A:B,2,FALSE)) | M23: =_xlfn.TEXTJOIN(";",TRUE,J23:L23)
A24: =IF(C24="","",VLOOKUP(C24,[1]ISO辞書!A:C,2,FALSE)) | B24: =IF(C24="","",VLOOKUP(C24,[1]ISO辞書!A:C,3,FALSE)) | J24: =IF(G24="","",VLOOKUP(G24,[1]ISO辞書!A:B,2,FALSE)) | K24: =IF(H24="","",VLOOKUP(H24,[1]ISO辞書!A:B,2,FALSE)) | L24: =IF(I24="","",VLOOKUP(I24,[1]ISO辞書!A:B,2,FALSE)) | M24: =_xlfn.TEXTJOIN(";",TRUE,J24:L24)
A25: =IF(C25="","",VLOOKUP(C25,[1]ISO辞書!A:C,2,FALSE)) | B25: =IF(C25="","",VLOOKUP(C25,[1]ISO辞書!A:C,3,FALSE)) | J25: =IF(G25="","",VLOOKUP(G25,[1]ISO辞書!A:B,2,FALSE)) | K25: =IF(H25="","",VLOOKUP(H25,[1]ISO辞書!A:B,2,FALSE)) | L25: =IF(I25="","",VLOOKUP(I25,[1]ISO辞書!A:B,2,FALSE)) | M25: =_xlfn.TEXTJOIN(";",TRUE,J25:L25)
A26: =IF(C26="","",VLOOKUP(C26,[1]ISO辞書!A:C,2,FALSE)) | B26: =IF(C26="","",VLOOKUP(C26,[1]ISO辞書!A:C,3,FALSE)) | J26: =IF(G26="","",VLOOKUP(G26,[1]ISO辞書!A:B,2,FALSE)) | K26: =IF(H26="","",VLOOKUP(H26,[1]ISO辞書!A:B,2,FALSE)) | L26: =IF(I26="","",VLOOKUP(I26,[1]ISO辞書!A:B,2,FALSE)) | M26: =_xlfn.TEXTJOIN(";",TRUE,J26:L26)
A27: =IF(C27="","",VLOOKUP(C27,[1]ISO辞書!A:C,2,FALSE)) | B27: =IF(C27="","",VLOOKUP(C27,[1]ISO辞書!A:C,3,FALSE)) | J27: =IF(G27="","",VLOOKUP(G27,[1]ISO辞書!A:B,2,FALSE)) | K27: =IF(H27="","",VLOOKUP(H27,[1]ISO辞書!A:B,2,FALSE)) | L27: =IF(I27="","",VLOOKUP(I27,[1]ISO辞書!A:B,2,FALSE)) | M27: =_xlfn.TEXTJOIN(";",TRUE,J27:L27)
A28: =IF(C28="","",VLOOKUP(C28,[1]ISO辞書!A:C,2,FALSE)) | B28: =IF(C28="","",VLOOKUP(C28,[1]ISO辞書!A:C,3,FALSE)) | J28: =IF(G28="","",VLOOKUP(G28,[1]ISO辞書!A:B,2,FALSE)) | K28: =IF(H28="","",VLOOKUP(H28,[1]ISO辞書!A:B,2,FALSE)) | L28: =IF(I28="","",VLOOKUP(I28,[1]ISO辞書!A:B,2,FALSE)) | M28: =_xlfn.TEXTJOIN(";",TRUE,J28:L28)
A29: =IF(C29="","",VLOOKUP(C29,[1]ISO辞書!A:C,2,FALSE)) | B29: =IF(C29="","",VLOOKUP(C29,[1]ISO辞書!A:C,3,FALSE)) | J29: =IF(G29="","",VLOOKUP(G29,[1]ISO辞書!A:B,2,FALSE)) | K29: =IF(H29="","",VLOOKUP(H29,[1]ISO辞書!A:B,2,FALSE)) | L29: =IF(I29="","",VLOOKUP(I29,[1]ISO辞書!A:B,2,FALSE)) | M29: =_xlfn.TEXTJOIN(";",TRUE,J29:L29)
A30: =IF(C30="","",VLOOKUP(C30,[1]ISO辞書!A:C,2,FALSE)) | B30: =IF(C30="","",VLOOKUP(C30,[1]ISO辞書!A:C,3,FALSE)) | J30: =IF(G30="","",VLOOKUP(G30,[1]ISO辞書!A:B,2,FALSE)) | K30: =IF(H30="","",VLOOKUP(H30,[1]ISO辞書!A:B,2,FALSE)) | L30: =IF(I30="","",VLOOKUP(I30,[1]ISO辞書!A:B,2,FALSE)) | M30: =_xlfn.TEXTJOIN(";",TRUE,J30:L30)
A31: =IF(C31="","",VLOOKUP(C31,[1]ISO辞書!A:C,2,FALSE)) | B31: =IF(C31="","",VLOOKUP(C31,[1]ISO辞書!A:C,3,FALSE)) | J31: =IF(G31="","",VLOOKUP(G31,[1]ISO辞書!A:B,2,FALSE)) | K31: =IF(H31="","",VLOOKUP(H31,[1]ISO辞書!A:B,2,FALSE)) | L31: =IF(I31="","",VLOOKUP(I31,[1]ISO辞書!A:B,2,FALSE)) | M31: =_xlfn.TEXTJOIN(";",TRUE,J31:L31)
A32: =IF(C32="","",VLOOKUP(C32,[1]ISO辞書!A:C,2,FALSE)) | B32: =IF(C32="","",VLOOKUP(C32,[1]ISO辞書!A:C,3,FALSE)) | J32: =IF(G32="","",VLOOKUP(G32,[1]ISO辞書!A:B,2,FALSE)) | K32: =IF(H32="","",VLOOKUP(H32,[1]ISO辞書!A:B,2,FALSE)) | L32: =IF(I32="","",VLOOKUP(I32,[1]ISO辞書!A:B,2,FALSE)) | M32: =_xlfn.TEXTJOIN(";",TRUE,J32:L32)
A33: =IF(C33="","",VLOOKUP(C33,[1]ISO辞書!A:C,2,FALSE)) | B33: =IF(C33="","",VLOOKUP(C33,[1]ISO辞書!A:C,3,FALSE)) | J33: =IF(G33="","",VLOOKUP(G33,[1]ISO辞書!A:B,2,FALSE)) | K33: =IF(H33="","",VLOOKUP(H33,[1]ISO辞書!A:B,2,FALSE)) | L33: =IF(I33="","",VLOOKUP(I33,[1]ISO辞書!A:B,2,FALSE)) | M33: =_xlfn.TEXTJOIN(";",TRUE,J33:L33)
A34: =IF(C34="","",VLOOKUP(C34,[1]ISO辞書!A:C,2,FALSE)) | B34: =IF(C34="","",VLOOKUP(C34,[1]ISO辞書!A:C,3,FALSE)) | J34: =IF(G34="","",VLOOKUP(G34,[1]ISO辞書!A:B,2,FALSE)) | K34: =IF(H34="","",VLOOKUP(H34,[1]ISO辞書!A:B,2,FALSE)) | L34: =IF(I34="","",VLOOKUP(I34,[1]ISO辞書!A:B,2,FALSE)) | M34: =_xlfn.TEXTJOIN(";",TRUE,J34:L34)
... A38: =IF(C38="","",VLOOKUP(C38,[1]ISO辞書!A:C,2,FALSE)) | B38: =IF(C38="","",VLOOKUP(C38,[1]ISO辞書!A:C,3,FALSE)) | J38: =IF(G38="","",VLOOKUP(G38,[1]ISO辞書!A:B,2,FALSE)) | K38: =IF(H38="","",VLOOKUP(H38,[1]ISO辞書!A:B,2,FALSE)) | L38: =IF(I38="","",VLOOKUP(I38,[1]ISO辞書!A:B,2,FALSE)) | M38: =_xlfn.TEXTJOIN(";",TRUE,J38:L38)
A39: =IF(C39="","",VLOOKUP(C39,[1]ISO辞書!A:C,2,FALSE)) | J39: =IF(G39="","",VLOOKUP(G39,[1]ISO辞書!A:B,2,FALSE)) | K39: =IF(H39="","",VLOOKUP(H39,[1]ISO辞書!A:B,2,FALSE)) | L39: =IF(I39="","",VLOOKUP(I39,[1]ISO辞書!A:B,2,FALSE)) | M39: =_xlfn.TEXTJOIN(";",TRUE,J39:L39)
A40: =IF(C40="","",VLOOKUP(C40,[1]ISO辞書!A:C,2,FALSE)) | J40: =IF(G40="","",VLOOKUP(G40,[1]ISO辞書!A:B,2,FALSE)) | K40: =IF(H40="","",VLOOKUP(H40,[1]ISO辞書!A:B,2,FALSE)) | L40: =IF(I40="","",VLOOKUP(I40,[1]ISO辞書!A:B,2,FALSE)) | M40: =_xlfn.TEXTJOIN(";",TRUE,J40:L40)
A41: =IF(C41="","",VLOOKUP(C41,[1]ISO辞書!A:C,2,FALSE)) | J41: =IF(G41="","",VLOOKUP(G41,[1]ISO辞書!A:B,2,FALSE)) | K41: =IF(H41="","",VLOOKUP(H41,[1]ISO辞書!A:B,2,FALSE)) | L41: =IF(I41="","",VLOOKUP(I41,[1]ISO辞書!A:B,2,FALSE)) | M41: =_xlfn.TEXTJOIN(";",TRUE,J41:L41)
A42: =IF(C42="","",VLOOKUP(C42,[1]ISO辞書!A:C,2,FALSE)) | J42: =IF(G42="","",VLOOKUP(G42,[1]ISO辞書!A:B,2,FALSE)) | K42: =IF(H42="","",VLOOKUP(H42,[1]ISO辞書!A:B,2,FALSE)) | L42: =IF(I42="","",VLOOKUP(I42,[1]ISO辞書!A:B,2,FALSE)) | M42: =_xlfn.TEXTJOIN(";",TRUE,J42:L42)
J43: =IF(G43="","",VLOOKUP(G43,[1]ISO辞書!A:B,2,FALSE)) | K43: =IF(H43="","",VLOOKUP(H43,[1]ISO辞書!A:B,2,FALSE)) | L43: =IF(I43="","",VLOOKUP(I43,[1]ISO辞書!A:B,2,FALSE)) | M43: =_xlfn.TEXTJOIN(";",TRUE,J43:L43)
...

Sheet リスト
B2: 国際関係に影響 | E2: 外交 | H2: 5
B3: 安全保障に影響 | E3: 軍事 | H3: 4
B4: 経済に影響 | E4: 安全保障 | H4: 3
B5: エネルギー市場に影響 | E5: 経済 | H5: 2
B6: 貿易に影響 | E6: エネルギー | H6: 1
B7: 金融市場に影響 | E7: 制裁
B8: 軍事的緊張が高まる | E8: 紛争
B9: 外交関係が悪化 | E9: 首脳会談
B10: 外交関係が改善 | E10: 貿易
B11: 地域情勢が不安定化 | E11: 金融
B12: 地域情勢が安定化 | E12: 国内政治
B13: 制裁強化 | E13: 人道
B14: 制裁緩和 | E14: テクノロジー
B15: サプライチェーンに影響 | E15: サイバー
B16: 国内政治に影響 | E16: その他
B17: 人道問題に影響
B18: 不明
