Workbook

Sheet events-入力用
A1: country_iso3 | B1: country_name | C1: country_name_ja | D1: title | E1: summary | F1: background | G1: impact | H1: future | I1: detail | J1: 関係国１ | K1: 関係国２ | L1: 関係国３ | M1: related_country_1 | N1: related_country_2 | O1: related_country_3 | P1: related_countries | Q1: impact_summary | R1: category | S1: event_date | T1: source_name | U1: source_url | V1: importance
A2: =IF(C2="","",VLOOKUP(C2,[1]ISO辞書!A:C,2,FALSE)) -> SVN | B2: =IF(C2="","",VLOOKUP(C2,[1]ISO辞書!A:C,3,FALSE)) -> Slovenia | C2: スロベニア | D2: スロベニア総選挙 | E2: スロベニアの総選挙が行われるも、与野党いずれも単独過半数を獲得できず、小党が連立の鍵を握る情勢となった | M2: =IF(J2="","",VLOOKUP(J2,[1]ISO辞書!A:B,2,FALSE)) | N2: =IF(K2="","",VLOOKUP(K2,[1]ISO辞書!A:B,2,FALSE)) | O2: =IF(L2="","",VLOOKUP(L2,[1]ISO辞書!A:B,2,FALSE)) | P2: =_xlfn.TEXTJOIN(";",TRUE,M2:O2) | Q2: 政局の不安定化は政策決定の遅れや対外姿勢の変化を招き、欧州での投資環境と対日関係にも影響を及ぼす可能性がある。 | R2: 国内政治 | S2: 46103 | T2: Reuters | U2: https://www.reuters.com/world/europe/slovenians-vote-tight-race-between-liberals-populist-right-2026-03-22/ | V2: 2
A3: =IF(C3="","",VLOOKUP(C3,[1]ISO辞書!A:C,2,FALSE)) -> TCD | B3: =IF(C3="","",VLOOKUP(C3,[1]ISO辞書!A:C,3,FALSE)) -> Chad | C3: チャド | D3: チャドがスーダン難民をめぐり国境へ軍を展開 | E3: チャドはスーダンからの越境ドローン攻撃を受け反撃準備を命じ、かつ国境地帯の難民約2,300人を内陸に緊急移転させ、国境における警戒を強めた | J3: スーダン | M3: =IF(J3="","",VLOOKUP(J3,[1]ISO辞書!A:B,2,FALSE)) -> SDN | N3: =IF(K3="","",VLOOKUP(K3,[1]ISO辞書!A:B,2,FALSE)) | O3: =IF(L3="","",VLOOKUP(L3,[1]ISO辞書!A:B,2,FALSE)) | P3: =_xlfn.TEXTJOIN(";",TRUE,M3:O3) -> SDN | Q3: 国境での戦闘と難民移動は域内の不安定化と人道支援需要を強め、日本の人道支援や国際的な安全保障協力にも影響を与える可能性がある。 | R3: 軍事 | S3: 46104 | T3: Reuters | U3: https://www.reuters.com/world/africa/chad-relocates-sudan-refugees-army-deploys-near-border-2026-03-23/ | V3: 1
A4: =IF(C4="","",VLOOKUP(C4,[1]ISO辞書!A:C,2,FALSE)) -> CRI | B4: =IF(C4="","",VLOOKUP(C4,[1]ISO辞書!A:C,3,FALSE)) -> Costa Rica | C4: コスタリカ | D4: コスタリカ、アメリカからの移民送還者受け入れへ | E4: アメリカとコスタリカは、米国が他国から送還する移民をコスタリカが受け入れる合意に署名した。週最大25人がコスタリカに移送され、米国が資金支援を行う。 | J4: アメリカ | M4: =IF(J4="","",VLOOKUP(J4,[1]ISO辞書!A:B,2,FALSE)) -> USA | N4: =IF(K4="","",VLOOKUP(K4,[1]ISO辞書!A:B,2,FALSE)) | O4: =IF(L4="","",VLOOKUP(L4,[1]ISO辞書!A:B,2,FALSE)) | P4: =_xlfn.TEXTJOIN(";",TRUE,M4:O4) -> USA | Q4: 中米の移民負担を分散し、米国の移民政策の運用負担の軽減が見込まれる。日本への直接影響は限定的だが、国際移民管理と多国間支援の在り方に示唆を与える。 | R4: 外交 | S4: 46104 | T4: Reuters | U4: https://www.reuters.com/world/americas/costa-rica-plans-accept-us-sent-migrants-other-countries-2026-03-24/ | V4: 4
A5: =IF(C5="","",VLOOKUP(C5,[1]ISO辞書!A:C,2,FALSE)) -> CHN | B5: =IF(C5="","",VLOOKUP(C5,[1]ISO辞書!A:C,3,FALSE)) -> China | C5: 中国 | D5: 香港警察、外国人へのパスワード取得権拡大 | E5: 香港政府が新法を制定し、警察にスマートフォンやコンピューターのパスワード提出を求める権限を付与した。これにより捜査当局は国家安全や重大犯罪の捜査でデジタル証拠へのアクセスを強化する。 | M5: =IF(J5="","",VLOOKUP(J5,[1]ISO辞書!A:B,2,FALSE)) | N5: =IF(K5="","",VLOOKUP(K5,[1]ISO辞書!A:B,2,FALSE)) | O5: =IF(L5="","",VLOOKUP(L5,[1]ISO辞書!A:B,2,FALSE)) | P5: =_xlfn.TEXTJOIN(";",TRUE,M5:O5) | Q5: 市民のプライバシー懸念が強まり、人権問題や対中投資判断、同国への渡航に影響を与える可能性がある。 | R5: 国内政治 | S5: 46104 | T5: Reuters | U5: https://www.reuters.com/world/china/hong-kong-police-given-new-powers-obtain-phone-computer-passwords-2026-03-23/ | V5: 5
A6: =IF(C6="","",VLOOKUP(C6,[1]ISO辞書!A:C,2,FALSE)) -> ISR | B6: =IF(C6="","",VLOOKUP(C6,[1]ISO辞書!A:C,3,FALSE)) -> Israel | C6: イスラエル | D6: イスラエル閣僚がレバノン南部を併合宣言 | E6: イスラエルの極右政党の大臣が南レバノンの併合を公に主張し、国土防衛と反テロをその理由に挙げた。声明は地域の軍事的緊張と国際的な非難を招いている。 | J6: レバノン | M6: =IF(J6="","",VLOOKUP(J6,[1]ISO辞書!A:B,2,FALSE)) -> LBN | N6: =IF(K6="","",VLOOKUP(K6,[1]ISO辞書!A:B,2,FALSE)) | O6: =IF(L6="","",VLOOKUP(L6,[1]ISO辞書!A:B,2,FALSE)) | P6: =_xlfn.TEXTJOIN(";",TRUE,M6:O6) -> LBN | Q6: 中東地域での緊張が高まり、海上輸送やエネルギー価格への波及が懸念。日本の外交・経済にも負担を及ぼす恐れがある。 | R6: 紛争 | S6: 46104 | T6: Reuters | U6: https://www.reuters.com/world/middle-east/israeli-minister-calls-annexation-southern-lebanon-2026-03-23/ | V6: 4
A7: =IF(C7="","",VLOOKUP(C7,[1]ISO辞書!A:C,2,FALSE)) -> ITA | B7: =IF(C7="","",VLOOKUP(C7,[1]ISO辞書!A:C,3,FALSE)) -> Italy | C7: イタリア | D7: イタリアの司法改革案が国民投票にて否決 | E7: 国民投票で与党が推進した司法改革案が否決され、メローニ首相の政治的影響力に打撃となった。投票率は約60%で反対が約54%を占めた。 | M7: =IF(J7="","",VLOOKUP(J7,[1]ISO辞書!A:B,2,FALSE)) | N7: =IF(K7="","",VLOOKUP(K7,[1]ISO辞書!A:B,2,FALSE)) | O7: =IF(L7="","",VLOOKUP(L7,[1]ISO辞書!A:B,2,FALSE)) | P7: =_xlfn.TEXTJOIN(";",TRUE,M7:O7) | Q7: メローニ政権の求心力低下が国内政局を不安定化させ、欧州での政策連携や対日関係にも影響を及ぼす可能性がある。 | R7: 国内政治 | S7: 46104 | T7: Reuters | U7: https://www.reuters.com/world/europe/exit-polls-suggest-italys-meloni-has-narrowly-lost-justice-referendum-vote-2026-03-23/ | V7: 5
A8: =IF(C8="","",VLOOKUP(C8,[1]ISO辞書!A:C,2,FALSE)) -> JPN | B8: =IF(C8="","",VLOOKUP(C8,[1]ISO辞書!A:C,3,FALSE)) -> Japan | C8: 日本 | D8: 日本、対中関係を「最重要」から格下げ | E8: 日本政府は2026年外交青書案にて、中国との関係を「最重要」との文言を外す方針を示し、対中政策を修正すると発表した。 | J8: 中国 | M8: =IF(J8="","",VLOOKUP(J8,[1]ISO辞書!A:B,2,FALSE)) -> CHN | N8: =IF(K8="","",VLOOKUP(K8,[1]ISO辞書!A:B,2,FALSE)) | O8: =IF(L8="","",VLOOKUP(L8,[1]ISO辞書!A:B,2,FALSE)) | P8: =_xlfn.TEXTJOIN(";",TRUE,M8:O8) -> CHN | Q8: 文言変更は日中関係の見直しを意味し、経済安全保障の観点から中国で活動する日経企業にも影響が生じうる。 | R8: 外交 | S8: 46105 | T8: Reuters | U8: https://www.reuters.com/world/china/japan-drop-most-important-tag-china-ties-2026-03-24/ | V8: 5
A9: =IF(C9="","",VLOOKUP(C9,[1]ISO辞書!A:C,2,FALSE)) -> ISR | B9: =IF(C9="","",VLOOKUP(C9,[1]ISO辞書!A:C,3,FALSE)) -> Israel | C9: イスラエル | D9: イスラエルがレバノン南部へ緩衝地帯設置計画を発表 | E9: イスラエルが南レバノンの一部を「緩衝地帯」として分離する計画を進め、同地域のインフラや市民に被害が発生している。 | J9: レバノン | M9: =IF(J9="","",VLOOKUP(J9,[1]ISO辞書!A:B,2,FALSE)) -> LBN | N9: =IF(K9="","",VLOOKUP(K9,[1]ISO辞書!A:B,2,FALSE)) | O9: =IF(L9="","",VLOOKUP(L9,[1]ISO辞書!A:B,2,FALSE)) | P9: =_xlfn.TEXTJOIN(";",TRUE,M9:O9) -> LBN | Q9: イスラエル軍による攻撃は中東地域における対立の構図を強め、地域の不安定化から中東からのエネルギー供給に影響の出る可能性がある。 | R9: 紛争 | S9: 46105 | T9: Reuters | U9: https://www.reuters.com/graphics/IRAN-CRISIS/LEBANON-ISRAEL-INFRASTRUCTURE/gkvlklaxypb/ | V9: 5
A10: =IF(C10="","",VLOOKUP(C10,[1]ISO辞書!A:C,2,FALSE)) -> EU | B10: =IF(C10="","",VLOOKUP(C10,[1]ISO辞書!A:C,3,FALSE)) -> EU | C10: 欧州連合 | D10: 欧州連合・オーストラリアが貿易協定を締結 | E10: EUとオーストラリアが包括的通商協定で合意し、関税の削減やサービス分野の市場開放、投資保護などの主要条項が発表された。 | J10: オーストラリア | M10: =IF(J10="","",VLOOKUP(J10,[1]ISO辞書!A:B,2,FALSE)) -> AUS | N10: =IF(K10="","",VLOOKUP(K10,[1]ISO辞書!A:B,2,FALSE)) | O10: =IF(L10="","",VLOOKUP(L10,[1]ISO辞書!A:B,2,FALSE)) | P10: =_xlfn.TEXTJOIN(";",TRUE,M10:O10) -> AUS | Q10: 新協定によりEUとオーストラリア間の貿易が活性化され、日本企業の国際競争にも影響を与え得る。 | R10: 貿易 | S10: 46105 | T10: Reuters | U10: https://www.reuters.com/business/highlights-eu-australia-trade-agreement-2026-03-24/ | V10: 5
A11: =IF(C11="","",VLOOKUP(C11,[1]ISO辞書!A:C,2,FALSE)) -> MEX | B11: =IF(C11="","",VLOOKUP(C11,[1]ISO辞書!A:C,3,FALSE)) -> Mexico | C11: メキシコ | D11: メキシコがキューバ医師協定維持を表明 | E11: メキシコ政府は、医療人材不足を補うためのキューバとの意思協定を維持すると表明し、同国の医療を支える姿勢を示した。 | J11: キューバ | M11: =IF(J11="","",VLOOKUP(J11,[1]ISO辞書!A:B,2,FALSE)) -> CUB | N11: =IF(K11="","",VLOOKUP(K11,[1]ISO辞書!A:B,2,FALSE)) | O11: =IF(L11="","",VLOOKUP(L11,[1]ISO辞書!A:B,2,FALSE)) | P11: =_xlfn.TEXTJOIN(";",TRUE,M11:O11) -> CUB | R11: 外交 | S11: 46106 | T11: Reuters | U11: https://www.reuters.com/world/americas/mexico-uphold-cuban-doctor-agreement-president-says-2026-03-25/ | V11: 2
A12: =IF(C12="","",VLOOKUP(C12,[1]ISO辞書!A:C,2,FALSE)) -> CYP | B12: =IF(C12="","",VLOOKUP(C12,[1]ISO辞書!A:C,3,FALSE)) -> Cyprus | C12: キプロス | D12: キプロス、イギリスと基地協議 | E12: キプロスが同国内にあるイギリス軍の基地について、イギリスと協議を開始したと発表。基地の運用や権限を巡る対話が開始される。 | J12: イギリス | M12: =IF(J12="","",VLOOKUP(J12,[1]ISO辞書!A:B,2,FALSE)) -> GBR | N12: =IF(K12="","",VLOOKUP(K12,[1]ISO辞書!A:B,2,FALSE)) | O12: =IF(L12="","",VLOOKUP(L12,[1]ISO辞書!A:B,2,FALSE)) | P12: =_xlfn.TEXTJOIN(";",TRUE,M12:O12) -> GBR | Q12: 地中海での安全保障協定が進めば、地中海における輸送航路の安定化が期待される。 | R12: 安全保障 | S12: 46106 | T12: Reuters | U12: https://www.reuters.com/world/uk/cyprus-has-opened-discussion-with-uk-over-its-bases-president-says-2026-03-25/ | V12: 4
A13: =IF(C13="","",VLOOKUP(C13,[1]ISO辞書!A:C,2,FALSE)) -> DNK | B13: =IF(C13="","",VLOOKUP(C13,[1]ISO辞書!A:C,3,FALSE)) -> Denmark | C13: デンマーク | D13: デンマーク首相が辞任表明 | E13: デンマークのフリデリクセン首相は選挙での敗北を受け辞任を表明。政権移行の手続きと新政権樹立の準備が始まる | M13: =IF(J13="","",VLOOKUP(J13,[1]ISO辞書!A:B,2,FALSE)) | N13: =IF(K13="","",VLOOKUP(K13,[1]ISO辞書!A:B,2,FALSE)) | O13: =IF(L13="","",VLOOKUP(L13,[1]ISO辞書!A:B,2,FALSE)) | P13: =_xlfn.TEXTJOIN(";",TRUE,M13:O13) | Q13: 政権交代はデンマークの国内外の政策見直しを招き、北欧諸国との協調やEU政策に影響を与える可能性がある。 | R13: 国内政治 | S13: 46106 | T13: Reuters | U13: https://www.reuters.com/world/europe/denmarks-prime-minister-hands-government-resignation-after-election-defeat-2026-03-25/ | V13: 3
A14: =IF(C14="","",VLOOKUP(C14,[1]ISO辞書!A:C,2,FALSE)) -> GBR | B14: =IF(C14="","",VLOOKUP(C14,[1]ISO辞書!A:C,3,FALSE)) -> Britain | C14: イギリス | D14: イギリスとトルコが防空協定に署名 | E14: イギリスとトルコが戦闘機20機の導入に向けた訓練・支援契約に署名、総額80億ポンドの合意を前進させた。 | J14: トルコ | M14: =IF(J14="","",VLOOKUP(J14,[1]ISO辞書!A:B,2,FALSE)) -> TUR | N14: =IF(K14="","",VLOOKUP(K14,[1]ISO辞書!A:B,2,FALSE)) | O14: =IF(L14="","",VLOOKUP(L14,[1]ISO辞書!A:B,2,FALSE)) | P14: =_xlfn.TEXTJOIN(";",TRUE,M14:O14) -> TUR | Q14: NATO東側の防空強化につながり、欧州の防衛産業と安全保障協力の流れを後押しする。日本の装備調達議論にも参考になりうる。 | R14: 安全保障 | S14: 46106 | T14: Reuters | U14: https://www.reuters.com/business/aerospace-defense/uk-turkey-sign-multi-billion-pound-air-defence-deal-2026-03-25/ | V14: 4
A15: =IF(C15="","",VLOOKUP(C15,[1]ISO辞書!A:C,2,FALSE)) -> KEN | B15: =IF(C15="","",VLOOKUP(C15,[1]ISO辞書!A:C,3,FALSE)) -> Kenya | C15: ケニア | D15: ケニアが中国との貿易協定に最終合意 | E15: ケニアのルト大統領は、中国との貿易交渉がまとまり、ケニアの輸出品の98％に関税ゼロを認める最終的な合意が取られたと発表した | J15: 中国 | M15: =IF(J15="","",VLOOKUP(J15,[1]ISO辞書!A:B,2,FALSE)) -> CHN | N15: =IF(K15="","",VLOOKUP(K15,[1]ISO辞書!A:B,2,FALSE)) | O15: =IF(L15="","",VLOOKUP(L15,[1]ISO辞書!A:B,2,FALSE)) | P15: =_xlfn.TEXTJOIN(";",TRUE,M15:O15) -> CHN | Q15: 中国のアフリカ進出が一段と進み、資源や市場をめぐる競争が強まる。日本企業のアフリカ展開にも影響しうる。 | R15: 貿易 | S15: 46106 | T15: Reuters | U15: https://www.reuters.com/world/africa/kenya-finalises-trade-deal-with-china-president-says-2026-03-25/ | V15: 3
A16: =IF(C16="","",VLOOKUP(C16,[1]ISO辞書!A:C,2,FALSE)) -> USA | B16: =IF(C16="","",VLOOKUP(C16,[1]ISO辞書!A:C,3,FALSE)) -> America | C16: アメリカ | D16: トランプ氏、マドゥロ大統領への追加訴追を示唆 | E16: トランプ大統領は、拘束中のベネズエラのマドゥロ氏について、追加の訴追を進めると表明した。 | J16: ベネズエラ | M16: =IF(J16="","",VLOOKUP(J16,[1]ISO辞書!A:B,2,FALSE)) -> VEN | N16: =IF(K16="","",VLOOKUP(K16,[1]ISO辞書!A:B,2,FALSE)) | O16: =IF(L16="","",VLOOKUP(L16,[1]ISO辞書!A:B,2,FALSE)) | P16: =_xlfn.TEXTJOIN(";",TRUE,M16:O16) -> VEN | Q16: アメリカの対ベネズエラ圧力が強まれば、移民問題や原油市場の不安定化が続き、日本にも間接的な影響が及ぶ。 | R16: 外交 | S16: 46107 | T16: Reuters | U16: https://www.reuters.com/world/americas/trump-says-venezuelas-maduro-face-additional-charges-2026-03-26/ | V16: 3
A17: =IF(C17="","",VLOOKUP(C17,[1]ISO辞書!A:C,2,FALSE)) -> PAK | B17: =IF(C17="","",VLOOKUP(C17,[1]ISO辞書!A:C,3,FALSE)) -> Pakistan | C17: パキスタン | D17: パキスタン、アフガニスタンで軍事作戦継続 | E17: パキスタン外務省は、アフガニスタンへの軍事行動を再開したと発表し、停戦への期待が後退した。 | J17: アフガニスタン | M17: =IF(J17="","",VLOOKUP(J17,[1]ISO辞書!A:B,2,FALSE)) -> AFG | N17: =IF(K17="","",VLOOKUP(K17,[1]ISO辞書!A:B,2,FALSE)) | O17: =IF(L17="","",VLOOKUP(L17,[1]ISO辞書!A:B,2,FALSE)) | P17: =_xlfn.TEXTJOIN(";",TRUE,M17:O17) -> AFG | Q17: イラン情勢を含めた中東から南アジア地域での緊張拡大が危惧される。物流に影響が出るほか、日本企業の中東やアジアにおける事業にもリスク要因となる。 | R17: 紛争 | S17: 46107 | T17: Reuters | U17: https://www.reuters.com/world/asia-pacific/pakistan-continuing-military-operations-against-afghanistan-pakistan-foreign-2026-03-26/ | V17: 5
A18: =IF(C18="","",VLOOKUP(C18,[1]ISO辞書!A:C,2,FALSE)) -> USA | B18: =IF(C18="","",VLOOKUP(C18,[1]ISO辞書!A:C,3,FALSE)) -> America | C18: アメリカ | D18: トランプ大統領、イランのエネルギー施設への攻撃を一時停止 | E18: トランプ大統領は、イランの要請を受けてエネルギー施設への攻撃を10日間止めるとし、停戦交渉は順調だと述べた。イラン側はアメリカ側の停戦案を不公平だと批判した。 | J18: イラン | M18: =IF(J18="","",VLOOKUP(J18,[1]ISO辞書!A:B,2,FALSE)) -> IRN | N18: =IF(K18="","",VLOOKUP(K18,[1]ISO辞書!A:B,2,FALSE)) | O18: =IF(L18="","",VLOOKUP(L18,[1]ISO辞書!A:B,2,FALSE)) | P18: =_xlfn.TEXTJOIN(";",TRUE,M18:O18) -> IRN | Q18: 中東の緊張が和らげば原油高の圧力は弱まるが、交渉が崩れれば日本のエネルギー輸入コスト高が危惧される。 | R18: 紛争 | S18: 46107 | T18: Reuters | U18: https://www.reuters.com/world/asia-pacific/iran-says-it-is-reviewing-us-ceasefire-plan-no-talks-trump-says-tehran-leaders-2026-03-26/ | V18: 5
A19: =IF(C19="","",VLOOKUP(C19,[1]ISO辞書!A:C,2,FALSE)) -> IRN | B19: =IF(C19="","",VLOOKUP(C19,[1]ISO辞書!A:C,3,FALSE)) -> Iran | C19: イラン | D19: アメリカがアラクチ外相らを攻撃対象から一時解除 | E19: パキスタンの要請により、イランのアラグチ外相とカリバフ議長がアメリカとイスラエルの攻撃対象から外された。 | J19: アメリカ | K19: パキスタン | M19: =IF(J19="","",VLOOKUP(J19,[1]ISO辞書!A:B,2,FALSE)) -> USA | N19: =IF(K19="","",VLOOKUP(K19,[1]ISO辞書!A:B,2,FALSE)) -> PAK | O19: =IF(L19="","",VLOOKUP(L19,[1]ISO辞書!A:B,2,FALSE)) | P19: =_xlfn.TEXTJOIN(";",TRUE,M19:O19) -> USA;PAK | Q19: パキスタンの仲介による対話継続により停戦成立が期待されるが状況は不透明。 | R19: 紛争 | S19: 46107 | T19: Reuters | U19: https://www.reuters.com/world/asia-pacific/israel-took-irans-araqchi-qalibaf-off-hit-list-pakistan-request-pakistani-2026-03-26/ | V19: 5
A20: =IF(C20="","",VLOOKUP(C20,[1]ISO辞書!A:C,2,FALSE)) -> UKR | B20: =IF(C20="","",VLOOKUP(C20,[1]ISO辞書!A:C,3,FALSE)) -> Ukraine | C20: ウクライナ | D20: ウクライナ、ロシアのエネルギー施設へ圧力 | E20: ゼレンスキー大統領は、国際的なロシアへの石油制裁が緩んだ後も、長距離攻撃で石油施設を狙い圧力をかけ続ける方針だと述べた。 | J20: ロシア | M20: =IF(J20="","",VLOOKUP(J20,[1]ISO辞書!A:B,2,FALSE)) -> RUS | N20: =IF(K20="","",VLOOKUP(K20,[1]ISO辞書!A:B,2,FALSE)) | O20: =IF(L20="","",VLOOKUP(L20,[1]ISO辞書!A:B,2,FALSE)) | P20: =_xlfn.TEXTJOIN(";",TRUE,M20:O20) -> RUS | Q20: ロシア産原油の輸出混乱はエネルギー価格を押し上げやすく、資源輸入国の日本にはコスト上昇圧力となる。 | R20: 紛争 | S20: 46107 | T20: Reuters | U20: https://www.reuters.com/business/energy/ukraine-using-strikes-pressure-russia-after-oil-sanctions-eased-zelenskiy-says-2026-03-26/ | V20: 5
A21: =IF(C21="","",VLOOKUP(C21,[1]ISO辞書!A:C,2,FALSE)) -> USA | B21: =IF(C21="","",VLOOKUP(C21,[1]ISO辞書!A:C,3,FALSE)) -> America | C21: アメリカ | D21: トランプ大統領、次はキューバ言及 | E21: トランプ大統領が演説で軍事成果を強調し、次の標的としてキューバに言及。緊張拡大の懸念が浮上。 | J21: キューバ | M21: =IF(J21="","",VLOOKUP(J21,[1]ISO辞書!A:B,2,FALSE)) -> CUB | N21: =IF(K21="","",VLOOKUP(K21,[1]ISO辞書!A:B,2,FALSE)) | O21: =IF(L21="","",VLOOKUP(L21,[1]ISO辞書!A:B,2,FALSE)) | P21: =_xlfn.TEXTJOIN(";",TRUE,M21:O21) -> CUB | Q21: 対キューバ圧力が強まれば中南米の緊張が増し、資源市場や日系企業の南米事業にも波及しうる。 | R21: 軍事 | S21: 46108 | T21: Reuters | U21: https://www.reuters.com/world/americas/trump-says-cuba-is-next-speech-touting-us-military-successes-2026-03-27/ | V21: 4
A22: =IF(C22="","",VLOOKUP(C22,[1]ISO辞書!A:C,2,FALSE)) -> CAN | B22: =IF(C22="","",VLOOKUP(C22,[1]ISO辞書!A:C,3,FALSE)) -> Canada | C22: カナダ | D22: カナダ、メルコスール協定狙う | E22: カナダがメルコスールとの自由貿易協定締結に向けた交渉加速を表明。2026年9～10月の署名と年内の合意が目標であると発表される。 | J22: ブラジル | K22: アルゼンチン | L22: パラグアイ | M22: =IF(J22="","",VLOOKUP(J22,[1]ISO辞書!A:B,2,FALSE)) -> BRA | N22: =IF(K22="","",VLOOKUP(K22,[1]ISO辞書!A:B,2,FALSE)) -> ARG | O22: =IF(L22="","",VLOOKUP(L22,[1]ISO辞書!A:B,2,FALSE)) -> PRY | P22: =_xlfn.TEXTJOIN(";",TRUE,M22:O22) -> BRA;ARG;PRY | Q22: アメリカとカナダの関係悪化により、北米と南米における新たな貿易協定の締結の可能性。サプライチェーン再編が進み日本企業の進出戦略やサプライチェーンにも影響。 | R22: 貿易 | S22: 46108 | T22: Reuters | U22: https://www.reuters.com/world/canada-eyes-mercosur-pact-by-autumn-2026-03-27/ | V22: 4
A23: =IF(C23="","",VLOOKUP(C23,[1]ISO辞書!A:C,2,FALSE)) -> EU | B23: =IF(C23="","",VLOOKUP(C23,[1]ISO辞書!A:C,3,FALSE)) -> EU | C23: 欧州連合 | D23: EＵとTPPがデジタル分野の合意を形成 | E23: EUとCPTPP参加国は、越境ECやデータ流通を含むデジタル貿易協定の協議を進めることで一致。カナダの貿易相は歴史的合意になりうると述べた。 | J23: CPTPP | M23: =IF(J23="","",VLOOKUP(J23,[1]ISO辞書!A:B,2,FALSE)) -> CPTPP | N23: =IF(K23="","",VLOOKUP(K23,[1]ISO辞書!A:B,2,FALSE)) | O23: =IF(L23="","",VLOOKUP(L23,[1]ISO辞書!A:B,2,FALSE)) | P23: =_xlfn.TEXTJOIN(";",TRUE,M23:O23) -> CPTPP | Q23: 日本を含むCPTPP域内でデジタル取引の標準化が進めば、越境ECやデータ連携がしやすくなり、日本企業にも追い風となる。 | R23: 貿易 | S23: 46108 | T23: Reuters | U23: https://www.reuters.com/world/americas/eu-cptpp-agree-progress-with-historic-digital-trade-deal-canadas-international-2026-03-27/ | V23: 5
A24: =IF(C24="","",VLOOKUP(C24,[1]ISO辞書!A:C,2,FALSE)) -> NPL | B24: =IF(C24="","",VLOOKUP(C24,[1]ISO辞書!A:C,3,FALSE)) -> Nepal | C24: ネパール | D24: ネパール首相にシャー氏が就任 | E24: シャハ氏がネパール首相に就任。雇用創出と政治的安定の回復が期待される。若者世代の抗議活動による政治的変動から、再建を進める局面に入った。 | M24: =IF(J24="","",VLOOKUP(J24,[1]ISO辞書!A:B,2,FALSE)) | N24: =IF(K24="","",VLOOKUP(K24,[1]ISO辞書!A:B,2,FALSE)) | O24: =IF(L24="","",VLOOKUP(L24,[1]ISO辞書!A:B,2,FALSE)) | P24: =_xlfn.TEXTJOIN(";",TRUE,M24:O24) | Q24: ネパールの政局が安定すれば南アジアの不確実性は和らぐが、混乱が続けば周辺国との経済関係にも響く可能性。 | R24: その他 | S24: 46108 | T24: Reuters | U24: https://www.reuters.com/world/china/ex-rapper-shah-sworn-nepal-prime-minister-after-sweeping-election-win-2026-03-27/ | V24: 2
A25: =IF(C25="","",VLOOKUP(C25,[1]ISO辞書!A:C,2,FALSE)) -> PRK | B25: =IF(C25="","",VLOOKUP(C25,[1]ISO辞書!A:C,3,FALSE)) -> North Korea | C25: 北朝鮮 | D25: 北朝鮮とベラルーシが友好条約に署名 | E25: 金正恩総書記とルカシェンコ大統領が平壌で会談し、友好条約と外交・農業・教育・公衆衛生などの協力文書に署名。両国関係が格上げされた。 | J25: ベラルーシ | M25: =IF(J25="","",VLOOKUP(J25,[1]ISO辞書!A:B,2,FALSE)) -> BLR | N25: =IF(K25="","",VLOOKUP(K25,[1]ISO辞書!A:B,2,FALSE)) | O25: =IF(L25="","",VLOOKUP(L25,[1]ISO辞書!A:B,2,FALSE)) | P25: =_xlfn.TEXTJOIN(";",TRUE,M25:O25) -> BLR | Q25: 北朝鮮の対外連携が広がれば制裁による包囲網の効果が弱まり、東アジアの安全保障に不安が残る。 | R25: 外交 | S25: 46108 | T25: Reuters | U25: https://www.reuters.com/world/asia-pacific/north-korea-belarus-sign-friendship-treaty-kcna-says-2026-03-26/ | V25: 5
A26: =IF(C26="","",VLOOKUP(C26,[1]ISO辞書!A:C,2,FALSE)) -> UKR | B26: =IF(C26="","",VLOOKUP(C26,[1]ISO辞書!A:C,3,FALSE)) -> Ukraine | C26: ウクライナ | D26: ウクライナとサウジアラビアが防衛協力に合意 | E26: ウクライナとサウジアラビアが防衛協力協定を結び、将来の契約や技術協力、投資の土台になるとゼレンスキー大統領が表明。アメリカの支援不透明感が強まる中、湾岸地域での支持を広げる狙いがある。 | J26: サウジアラビア | M26: =IF(J26="","",VLOOKUP(J26,[1]ISO辞書!A:B,2,FALSE)) -> SAU | N26: =IF(K26="","",VLOOKUP(K26,[1]ISO辞書!A:B,2,FALSE)) | O26: =IF(L26="","",VLOOKUP(L26,[1]ISO辞書!A:B,2,FALSE)) | P26: =_xlfn.TEXTJOIN(";",TRUE,M26:O26) -> SAU | Q26: 支援の軸が欧米以外にも広がれば、ロシアとの戦争の長期化への備えと、中東における外交の再編が進む。日本にも原油や安全保障面での影響が及ぶ可能性あり。 | R26: 安全保障 | S26: 46108 | T26: Reuters | U26: https://www.reuters.com/business/aerospace-defense/ukraine-saudi-arabia-sign-deal-defence-cooperation-zelenskiy-says-2026-03-27/ | V26: 5
A27: =IF(C27="","",VLOOKUP(C27,[1]ISO辞書!A:C,2,FALSE)) -> COD | B27: =IF(C27="","",VLOOKUP(C27,[1]ISO辞書!A:C,3,FALSE)) -> Democratic Republic of the Congo | C27: コンゴ民主共和国 | D27: DRコンゴが中国との鉱業協力強化 | E27: コンゴ民主共和国は中国と鉱山分野の協力を深める合意を締結。コバルトの最大産地をめぐり、米中が影響力を競う構図が強まっている。 | J27: 中国 | M27: =IF(J27="","",VLOOKUP(J27,[1]ISO辞書!A:B,2,FALSE)) -> CHN | N27: =IF(K27="","",VLOOKUP(K27,[1]ISO辞書!A:B,2,FALSE)) | O27: =IF(L27="","",VLOOKUP(L27,[1]ISO辞書!A:B,2,FALSE)) | P27: =_xlfn.TEXTJOIN(";",TRUE,M27:O27) -> CHN | Q27: リチウムイオン電池の原料の供給網に直結するため、日本のEVや蓄電池産業の調達先分散にも関係しうる。 | R27: 貿易 | S27: 46108 | T27: Reuters | U27: https://www.reuters.com/world/africa/congo-china-deepen-mining-ties-us-pushes-rival-minerals-pact-2026-03-27/ | V27: 4
A28: =IF(C28="","",VLOOKUP(C28,[1]ISO辞書!A:C,2,FALSE)) -> CHN | B28: =IF(C28="","",VLOOKUP(C28,[1]ISO辞書!A:C,3,FALSE)) -> China | C28: 中国 | D28: 比中、南シナ海協議再開へ | E28: フィリピンと中国が南シナ海をめぐる高官協議を約1年ぶりに再開。石油や天然ガス調達における協力や、エネルギー・肥料の供給安定を協議した。比マルコス大統領が国家エネルギー非常事態を宣言した直後の対話。 | J28: フィリピン | M28: =IF(J28="","",VLOOKUP(J28,[1]ISO辞書!A:B,2,FALSE)) -> PHL | N28: =IF(K28="","",VLOOKUP(K28,[1]ISO辞書!A:B,2,FALSE)) | O28: =IF(L28="","",VLOOKUP(L28,[1]ISO辞書!A:B,2,FALSE)) | P28: =_xlfn.TEXTJOIN(";",TRUE,M28:O28) -> PHL | Q28: 海上摩擦の緩和は海運とエネルギー市場の安定に寄与し、日本の燃料調達リスクの抑制にもつながる。 | R28: 安全保障 | S28: 46109 | T28: Reuters | U28: https://www.reuters.com/business/energy/manila-beijing-resume-talks-south-china-sea-energy-security-2026-03-28/ | V28: 4
A29: =IF(C29="","",VLOOKUP(C29,[1]ISO辞書!A:C,2,FALSE)) -> IDN | B29: =IF(C29="","",VLOOKUP(C29,[1]ISO辞書!A:C,3,FALSE)) -> Indonesia | C29: インドネシア | D29: インドネシア、未成年SNS規制が施行 | E29: インドネシアが16歳未満のSNS利用を制限する新ルールを開始。運用方法にはなお不透明さが残る。 | M29: =IF(J29="","",VLOOKUP(J29,[1]ISO辞書!A:B,2,FALSE)) | N29: =IF(K29="","",VLOOKUP(K29,[1]ISO辞書!A:B,2,FALSE)) | O29: =IF(L29="","",VLOOKUP(L29,[1]ISO辞書!A:B,2,FALSE)) | P29: =_xlfn.TEXTJOIN(";",TRUE,M29:O29) | Q29: 未成年への保護強化は、アジアのSNS事業者に年齢確認と監視強化を迫り、日本の規制議論にも影響が起きうる。 | R29: その他 | S29: 46109 | T29: Reuters | U29: https://www.reuters.com/business/media-telecom/indonesias-social-media-curbs-kids-set-saturday-few-know-how-it-will-work-2026-03-27/ | V29: 3
A30: =IF(C30="","",VLOOKUP(C30,[1]ISO辞書!A:C,2,FALSE)) -> UKR | B30: =IF(C30="","",VLOOKUP(C30,[1]ISO辞書!A:C,3,FALSE)) -> Ukraine | C30: ウクライナ | D30: ウクライナがUAE・カタールと防衛協力 | E30: ウクライナがUAEと防衛分野で協力に合意。カタールともミサイルや無人機対策を含む協定を結んだ。ゼレンスキー大統領は湾岸歴訪で支援の幅を広げようとしている。 | J30: UAE | K30: カタール | M30: =IF(J30="","",VLOOKUP(J30,[1]ISO辞書!A:B,2,FALSE)) -> ARE | N30: =IF(K30="","",VLOOKUP(K30,[1]ISO辞書!A:B,2,FALSE)) -> QAT | O30: =IF(L30="","",VLOOKUP(L30,[1]ISO辞書!A:B,2,FALSE)) | P30: =_xlfn.TEXTJOIN(";",TRUE,M30:O30) -> ARE;QAT | Q30: ウクライナと湾岸諸国との結びつきが強まることで欧米中心の同国への支援が多角化が期待。中東を含む国際秩序の変化は日本の経済外交にも関係が及びうる。 | R30: 安全保障 | S30: 46109 | T30: Reuters | U30: https://www.reuters.com/world/middle-east/ukraine-uae-agree-cooperate-defence-zelenskiy-says-2026-03-28/ | V30: 5
A31: =IF(C31="","",VLOOKUP(C31,[1]ISO辞書!A:C,2,FALSE)) -> NPL | B31: =IF(C31="","",VLOOKUP(C31,[1]ISO辞書!A:C,3,FALSE)) -> Nepal | C31: ネパール | D31: ネパールの前首相が逮捕される | E31: ネパール警察が前首相のオリ氏を逮捕。2025年9月の反汚職デモで多数の死者が出た対応を巡っての逮捕となる。 | M31: =IF(J31="","",VLOOKUP(J31,[1]ISO辞書!A:B,2,FALSE)) | N31: =IF(K31="","",VLOOKUP(K31,[1]ISO辞書!A:B,2,FALSE)) | O31: =IF(L31="","",VLOOKUP(L31,[1]ISO辞書!A:B,2,FALSE)) | P31: =_xlfn.TEXTJOIN(";",TRUE,M31:O31) | R31: 国内政治 | S31: 46109 | T31: Reuters | U31: https://www.reuters.com/world/asia-pacific/nepals-ex-pm-oli-held-over-deaths-during-gen-z-protests-2026-03-28/ | V31: 2
A32: =IF(C32="","",VLOOKUP(C32,[1]ISO辞書!A:C,2,FALSE)) -> YEM | B32: =IF(C32="","",VLOOKUP(C32,[1]ISO辞書!A:C,3,FALSE)) -> Yemen | C32: イエメン | D32: フーシ派がイランの戦線へ参加表明 | E32: パキスタンがイラン紛争の終結に向けた協議準備を進める一方、フーシ派がイスラエルへの攻撃に加わり、紅海周辺の海上輸送リスクが高まった。 | J32: イラン | K32: アメリカ | L32: イスラエル | M32: =IF(J32="","",VLOOKUP(J32,[1]ISO辞書!A:B,2,FALSE)) -> IRN | N32: =IF(K32="","",VLOOKUP(K32,[1]ISO辞書!A:B,2,FALSE)) -> USA | O32: =IF(L32="","",VLOOKUP(L32,[1]ISO辞書!A:B,2,FALSE)) -> ISR | P32: =_xlfn.TEXTJOIN(";",TRUE,M32:O32) -> IRN;USA;ISR | Q32: 中東の戦火が海路に広がれば原油と輸送費が上がり、日本のエネルギー調達にも直結する。 | R32: 紛争 | S32: 46110 | T32: Reuters | U32: https://www.reuters.com/world/asia-pacific/yemens-houthis-enter-iran-war-with-attacks-israel-while-us-marines-arrive-region-2026-03-28/ | V32: 5
A33: =IF(C33="","",VLOOKUP(C33,[1]ISO辞書!A:C,2,FALSE)) -> UKR | B33: =IF(C33="","",VLOOKUP(C33,[1]ISO辞書!A:C,3,FALSE)) -> Ukraine | C33: ウクライナ | D33: ゼレンスキー大統領のヨルダン訪問 | E33: ウクライナのゼレンスキー大統領はヨルダンのアブドラ国王と会談し、ドローン攻撃への対処を含む安全保障協力を協議。中東・湾岸地域での支援拡大を狙う。 | J33: ヨルダン | M33: =IF(J33="","",VLOOKUP(J33,[1]ISO辞書!A:B,2,FALSE)) -> JOR | N33: =IF(K33="","",VLOOKUP(K33,[1]ISO辞書!A:B,2,FALSE)) | O33: =IF(L33="","",VLOOKUP(L33,[1]ISO辞書!A:B,2,FALSE)) | P33: =_xlfn.TEXTJOIN(";",TRUE,M33:O33) -> JOR | Q33: 湾岸諸国の関与が深まれば、ウクライナ支援の裾野が広がり、軍事技術協力の流れも変わる可能性。 | R33: 外交 | S33: 46110 | T33: Reuters | U33: https://www.reuters.com/business/aerospace-defense/ukraines-zelenskiy-arrives-jordan-next-leg-gulf-tour-2026-03-29/ | V33: 2
A34: =IF(C34="","",VLOOKUP(C34,[1]ISO辞書!A:C,2,FALSE)) -> EGY | B34: =IF(C34="","",VLOOKUP(C34,[1]ISO辞書!A:C,3,FALSE)) -> Egypt | C34: エジプト | D34: アラブ連盟の事務総長にエジプト外交官が指名される | E34: アラブ諸国の外相らは、エジプトの外交官であるファヒミ氏をアラブ連盟事務総長に全会一致で指名した。 | M34: =IF(J34="","",VLOOKUP(J34,[1]ISO辞書!A:B,2,FALSE)) | N34: =IF(K34="","",VLOOKUP(K34,[1]ISO辞書!A:B,2,FALSE)) | O34: =IF(L34="","",VLOOKUP(L34,[1]ISO辞書!A:B,2,FALSE)) | P34: =_xlfn.TEXTJOIN(";",TRUE,M34:O34) | Q34: 中東外交の調整役の交代により、ガザ地区やイランをめぐる地域対話の進め方に影響が出る。 | R34: 外交 | S34: 46110 | T34: Reuters | U34: https://www.reuters.com/business/media-telecom/arab-foreign-ministers-name-nabil-fahmy-arab-league-chief-2026-03-29/ | V34: 3
A35: =IF(C35="","",VLOOKUP(C35,[1]ISO辞書!A:C,2,FALSE)) -> CUB | B35: =IF(C35="","",VLOOKUP(C35,[1]ISO辞書!A:C,3,FALSE)) -> Cuba | C35: キューバ | D35: ロシア原油がキューバに到着 | E35: ロシアが燃料不足のキューバへ原油を輸送し、深刻な人道危機を一時的にしのいだ。アメリカは同国への輸送を認めており、制裁運用の見方が分かれている。 | J35: ロシア | K35: アメリカ | M35: =IF(J35="","",VLOOKUP(J35,[1]ISO辞書!A:B,2,FALSE)) -> RUS | N35: =IF(K35="","",VLOOKUP(K35,[1]ISO辞書!A:B,2,FALSE)) -> USA | O35: =IF(L35="","",VLOOKUP(L35,[1]ISO辞書!A:B,2,FALSE)) | P35: =_xlfn.TEXTJOIN(";",TRUE,M35:O35) -> RUS;USA | Q35: キューバの原油調達が滞れば同国の政権が動揺しかねない事態が起きうる。 | R35: エネルギー | S35: 46111 | T35: Bloomberg | U35: https://www.bloomberg.com/news/articles/2026-03-30/russian-oil-shipment-buys-us-and-cuba-time-as-crisis-festers | V35: 3
A36: =IF(C36="","",VLOOKUP(C36,[1]ISO辞書!A:C,2,FALSE)) -> LBN | B36: =IF(C36="","",VLOOKUP(C36,[1]ISO辞書!A:C,3,FALSE)) -> Lebanon | C36: レバノン | D36: レバノン南部で国連平和維持軍3名が死亡 | E36: レバノン南部で、インドネシア出身の国連平和維持部隊の兵士3人が死亡。イスラエル軍の攻撃が続く中、UNIFILの安全が改めて問われている。 | J36: イスラエル | M36: =IF(J36="","",VLOOKUP(J36,[1]ISO辞書!A:B,2,FALSE)) -> ISR | N36: =IF(K36="","",VLOOKUP(K36,[1]ISO辞書!A:B,2,FALSE)) | O36: =IF(L36="","",VLOOKUP(L36,[1]ISO辞書!A:B,2,FALSE)) | P36: =_xlfn.TEXTJOIN(";",TRUE,M36:O36) -> ISR | Q36: 国連平和維持軍への被害拡大は、レバノン情勢の悪化を示し、中東の緊張と不安を長引かせる。 | R36: 紛争 | S36: 46111 | T36: Reuters | U36: https://www.reuters.com/world/middle-east/unifil-says-one-peacekeeper-killed-one-critically-injured-southern-lebanon-2026-03-29/ | V36: 2
A37: =IF(C37="","",VLOOKUP(C37,[1]ISO辞書!A:C,2,FALSE)) -> RUS | B37: =IF(C37="","",VLOOKUP(C37,[1]ISO辞書!A:C,3,FALSE)) -> Russian Federation | C37: ロシア | D37: ロシアがスパイ容疑で英外交官を追放 | E37: ロシアは経済スパイ活動に関与したとしてイギリスの外交官を追放。イギリスは容認できないと強く反発した。 | J37: イギリス | M37: =IF(J37="","",VLOOKUP(J37,[1]ISO辞書!A:B,2,FALSE)) -> GBR | N37: =IF(K37="","",VLOOKUP(K37,[1]ISO辞書!A:B,2,FALSE)) | O37: =IF(L37="","",VLOOKUP(L37,[1]ISO辞書!A:B,2,FALSE)) | P37: =_xlfn.TEXTJOIN(";",TRUE,M37:O37) -> GBR | Q37: 英露の対立が続けば、ウクライナ戦争をめぐる欧州の緊張がさらに強まり、対露制裁の流れにも影響する。 | R37: 外交 | S37: 46111 | T37: Reuters | U37: https://www.reuters.com/world/russia-expels-british-diplomat-over-espionage-fsb-says-2026-03-30/ | V37: 2
A38: =IF(C38="","",VLOOKUP(C38,[1]ISO辞書!A:C,2,FALSE)) -> AFG | B38: =IF(C38="","",VLOOKUP(C38,[1]ISO辞書!A:C,3,FALSE)) -> Afghanistan | C38: アフガニスタン | D38: アフガニスタンとパキスタンで豪雨被害 | E38: アフガニスタンとパキスタンで豪雨と洪水が発生し、合わせて45人が死亡。アフガンでは約130棟の建物が倒壊し、パキスタンでも多くの子どもが犠牲になった。 | J38: パキスタン | M38: =IF(J38="","",VLOOKUP(J38,[1]ISO辞書!A:B,2,FALSE)) -> PAK | N38: =IF(K38="","",VLOOKUP(K38,[1]ISO辞書!A:B,2,FALSE)) | O38: =IF(L38="","",VLOOKUP(L38,[1]ISO辞書!A:B,2,FALSE)) | P38: =_xlfn.TEXTJOIN(";",TRUE,M38:O38) -> PAK | R38: 人道 | S38: 46111 | T38: Reuters | U38: https://www.reuters.com/sustainability/climate-energy/heavy-rain-floods-kill-22-people-afghanistan-2026-03-30/ | V38: 1
A39: =IF(C39="","",VLOOKUP(C39,[1]ISO辞書!A:C,2,FALSE)) -> XKK | B39: =IF(C39="","",VLOOKUP(C39,[1]ISO辞書!A:C,3,FALSE)) -> Kosovo | C39: コソボ | D39: コソボがガザ地区への部隊派遣を承認 | E39: コソボ政府は、アメリカ主導の平和評議会の一員として、ガザへの部隊派遣を承認した。ガザ地区における停戦後の治安維持と暫定統治を支える構想の一部となる。 | J39: アメリカ | K39: イスラエル | L39: パレスチナ | M39: =IF(J39="","",VLOOKUP(J39,[1]ISO辞書!A:B,2,FALSE)) -> USA | N39: =IF(K39="","",VLOOKUP(K39,[1]ISO辞書!A:B,2,FALSE)) -> ISR | O39: =IF(L39="","",VLOOKUP(L39,[1]ISO辞書!A:B,2,FALSE)) -> PSE | P39: =_xlfn.TEXTJOIN(";",TRUE,M39:O39) -> USA;ISR;PSE | R39: 紛争 | S39: 46111 | T39: Reuters | U39: https://www.reuters.com/world/asia-pacific/kosovo-approves-troops-gaza-under-us-backed-scheme-2026-03-30/ | V39: 2
A40: =IF(C40="","",VLOOKUP(C40,[1]ISO辞書!A:C,2,FALSE)) -> PAK | B40: =IF(C40="","",VLOOKUP(C40,[1]ISO辞書!A:C,3,FALSE)) -> Pakistan | C40: パキスタン | D40: パキスタンとアフガニスタンが再衝突 | E40: アフガニスタンとパキスタンとの間で、停戦期間中に重火器での交戦が発生し、国境地帯の緊張が再び高まった。 | J40: アフガニスタン | M40: =IF(J40="","",VLOOKUP(J40,[1]ISO辞書!A:B,2,FALSE)) -> AFG | N40: =IF(K40="","",VLOOKUP(K40,[1]ISO辞書!A:B,2,FALSE)) | O40: =IF(L40="","",VLOOKUP(L40,[1]ISO辞書!A:B,2,FALSE)) | P40: =_xlfn.TEXTJOIN(";",TRUE,M40:O40) -> AFG | Q40: 国境衝突が続けば地域貿易や物流が不安定化し、南アジアの安全保障にも悪影響が及ぶ。 | R40: 紛争 | S40: 46111 | T40: Reuters | U40: https://www.reuters.com/world/asia-pacific/pakistan-afghanistan-trade-fire-islamabad-prepares-host-us-iran-talks-2026-03-30/ | V40: 4
...
